Workbook

Sheet Szamlaszamok
A1: Szamlazas/Szamlaszam | B1: Paciens/Nev | C1: Paciens/Azonosito | D1: Szamlazas/SzamlazasDatuma | E1: Szamlazas/NettoAr | F1: Szamlazas/Artetel
A2: HNG-2025-5809 | B2: Rábai Krisztina Dr. | C2: 083252864 | D2: 2025.09.15 10:06:00 | E2: 5000 | F2: Alfa-fötoprotein (AFP)
A3: HNG-2025-5814 | B3: Sós József Dr. | C3: 039710419 | D3: 2025.09.15 10:55:00 | E3: 5000 | F3: Alfa-fötoprotein (AFP)
A4: HNG-2025-5898 | B4: Tóth Erzsébet Dr. | C4: 075334019 | D4: 2025.09.19 09:25:00 | E4: 5000 | F4: Alfa-fötoprotein (AFP)
A5: HNG-2025-5933 | B5: Horváth Ágota Teréz Dr. | C5: 078327920 | D5: 2025.09.22 11:33:00 | E5: 5000 | F5: Alfa-fötoprotein (AFP)
A6: HNG-2025-5924 | B6: Kiss Artúr Endre | C6: 028578172 | D6: 2025.09.22 08:49:00 | E6: 500 | F6: Albumin
A7: HNG-2025-5956 | B7: Kindelmann Dóra Kata Dr. | C7: 092172300 | D7: 2025.09.24 07:25:00 | E7: 500 | F7: Albumin
A8: HNG-2025-5487 | B8: Pat McCrea | D8: 2025.09.01 13:54:00 | E8: 500 | F8: Albumin
A9: HNG-2025-5510 | B9: Rácz Gabriella | C9: 078476891 | D9: 2025.09.02 09:52:00 | E9: 500 | F9: Albumin
A10: HNG-2025-5591 | B10: Majoros Viktória | C10: 089671704 | D10: 2025.09.04 09:49:00 | E10: 500 | F10: Albumin
A11: HNG-2025-5956 | B11: Kindelmann Dóra Kata Dr. | C11: 092172300 | D11: 2025.09.24 07:25:00 | E11: 15000 | F11: Anti-Müllerian Hormon (AMH)
A12: HNG-2025-5920 | B12: Barna Beáta | C12: 089383597 | D12: 2025.09.22 08:05:00 | E12: 15000 | F12: Anti-Müllerian Hormon (AMH)
A13: HNG-2025-5956 | B13: Kindelmann Dóra Kata Dr. | C13: 092172300 | D13: 2025.09.24 07:25:00 | E13: 1000 | F13: Amiláz
A14: HNG-2025-5941 | B14: Kollmann Réka Zsuzsanna | C14: 080414919 | D14: 2025.09.22 15:05:00 | E14: 1000 | F14: Amiláz
A15: HNG-2025-5830 | B15: Karácsony Gábor Józsefné | C15: 084711911 | D15: 2025.09.15 13:56:00 | E15: 1000 | F15: Amiláz
A16: HNG-2025-5854 | B16: Török Levente | C16: 121104263 | D16: 2025.09.17 07:18:00 | E16: 1000 | F16: Amiláz
A17: HNG-2025-5775 | B17: Kéri Viktor Bence | C17: 040824039 | D17: 2025.09.12 11:44:00 | E17: 1000 | F17: Amiláz
A18: HNG-2025-5591 | B18: Majoros Viktória | C18: 089671704 | D18: 2025.09.04 09:49:00 | E18: 1000 | F18: Amiláz
A19: HNG-2025-5510 | B19: Rácz Gabriella | C19: 078476891 | D19: 2025.09.02 09:52:00 | E19: 1000 | F19: Amiláz
A20: ALDI-2025-17 | B20: Földing Anikó | C20: 109844707 | D20: 2025.09.30 07:22:00 | E20: 1000 | F20: Amiláz
A21: HNG-2025-5470 | B21: Czipri-Mándi József Gábor | C21: 041073924 | D21: 2025.09.01 09:22:00 | E21: 5000 | F21: Anti-TPO
A22: HNG-2025-5621 | B22: Krisán Andrea | C22: 090480823 | D22: 2025.09.05 12:21:00 | E22: 5000 | F22: Anti-TPO
A23: HNG-2025-5624 | B23: Dusekné Juranics Anikó | C23: 082426345 | D23: 2025.09.05 14:08:00 | E23: 5000 | F23: Anti-TPO
A24: MAESZ-2025-2629 | B24: Deák Veronika | C24: 086107093 | D24: 2025.09.14 15:34:00 | E24: 5000 | F24: Anti-TPO
A25: HNG-2025-5788 | B25: Halász-Kiss Judit | C25: 086855550 | D25: 2025.09.15 07:16:00 | E25: 5000 | F25: Anti-TPO
A26: HNG-2025-5862 | B26: Mikesy Álmos | C26: 039500704 | D26: 2025.09.17 11:14:00 | E26: 5000 | F26: Anti-TPO
A27: HNG-2025-5922 | B27: Kerti Dóra | C27: 091765084 | D27: 2025.09.22 08:37:00 | E27: 5000 | F27: Anti-TPO
A28: HNG-2025-5956 | B28: Kindelmann Dóra Kata Dr. | C28: 092172300 | D28: 2025.09.24 07:25:00 | E28: 2000 | F28: SYNLAB - AST
A29: HNG-2025-5586 | B29: Bokros Péter | C29: 138671170 | D29: 2025.09.04 08:47:00 | E29: 500 | F29: Direkt bilirubin
A30: HNG-2025-5467 | B30: Győri György Gyula | C30: 105841072 | D30: 2025.09.01 08:44:00 | E30: 500 | F30: Totál bilirubin
A31: HNG-2025-5487 | B31: Pat McCrea | D31: 2025.09.01 13:54:00 | E31: 500 | F31: Totál bilirubin
A32: HNG-2025-5586 | B32: Bokros Péter | C32: 138671170 | D32: 2025.09.04 08:47:00 | E32: 500 | F32: Totál bilirubin
A33: HNG-2025-5591 | B33: Majoros Viktória | C33: 089671704 | D33: 2025.09.04 09:49:00 | E33: 500 | F33: Totál bilirubin
A34: HNG-2025-5959 | B34: Selmeci Zsolt | C34: 017939553 | D34: 2025.09.24 09:20:00 | E34: 500 | F34: Totál bilirubin
A35: HNG-2025-5924 | B35: Kiss Artúr Endre | C35: 028578172 | D35: 2025.09.22 08:49:00 | E35: 500 | F35: Totál bilirubin
A36: HNG-2025-5980 | B36: Kanyó Gábor | C36: 028393014 | D36: 2025.09.25 09:14:00 | E36: 500 | F36: Totál bilirubin
A37: HNG-2025-6025 | B37: Rátonyi-Máté Judit | C37: 085937088 | D37: 2025.09.29 09:27:00 | E37: 500 | F37: Totál bilirubin
A38: HNG-2025-5933 | B38: Horváth Ágota Teréz Dr. | C38: 078327920 | D38: 2025.09.22 11:33:00 | E38: 5000 | F38: CEA
A39: HNG-2025-5898 | B39: Tóth Erzsébet Dr. | C39: 075334019 | D39: 2025.09.19 09:25:00 | E39: 5000 | F39: CEA
A40: MAESZ-2025-2612 | B40: Pappné Nagy Ilona | C40: 065641716 | D40: 2025.09.13 13:28:00 | E40: 5000 | F40: CEA
...

Sheet Szamlaszamok_nonduplicate
A1: Szamlazas/Szamlaszam | B1: Paciens/Nev | C1: Paciens/Azonosito | D1: Szamlazas/SzamlazasDatuma | H1: Szamlazas/Ossztetel | I1: Szamlazas/OsszNettoAr
A2: HNG-2025-5809 | B2: =VLOOKUP($A2,Szamlaszamok!$A1:F1557,2,FALSE) | C2: =VLOOKUP($A2,Szamlaszamok!$A1:F1557,3,FALSE) | D2: =VLOOKUP($A2,Szamlaszamok!$A1:F1557,4,FALSE) | E2: =DATE(YEAR(D2),MONTH(D2),DAY(D2)) | F2: =CONCATENATE(C2,E2) | G2: =TIMEVALUE(D2) | H2: =COUNTIF(Szamlaszamok!A:A,A2) | I2: =SUMIFS(Szamlaszamok!E:E,Szamlaszamok!A:A,Szamlaszamok_nonduplicate!A2)
A3: HNG-2025-5814 | B3: =VLOOKUP($A3,Szamlaszamok!$A2:F1558,2,FALSE) | C3: =VLOOKUP($A3,Szamlaszamok!$A2:F1558,3,FALSE) | D3: =VLOOKUP($A3,Szamlaszamok!$A2:F1558,4,FALSE) | E3: =DATE(YEAR(D3),MONTH(D3),DAY(D3)) | F3: =CONCATENATE(C3,E3) | G3: =TIMEVALUE(D3) | H3: =COUNTIF(Szamlaszamok!A:A,A3) | I3: =SUMIFS(Szamlaszamok!E:E,Szamlaszamok!A:A,Szamlaszamok_nonduplicate!A3)
A4: HNG-2025-5898 | B4: =VLOOKUP($A4,Szamlaszamok!$A3:F1559,2,FALSE) | C4: =VLOOKUP($A4,Szamlaszamok!$A3:F1559,3,FALSE) | D4: =VLOOKUP($A4,Szamlaszamok!$A3:F1559,4,FALSE) | E4: =DATE(YEAR(D4),MONTH(D4),DAY(D4)) | F4: =CONCATENATE(C4,E4) | G4: =TIMEVALUE(D4) | H4: =COUNTIF(Szamlaszamok!A:A,A4) | I4: =SUMIFS(Szamlaszamok!E:E,Szamlaszamok!A:A,Szamlaszamok_nonduplicate!A4)
A5: HNG-2025-5933 | B5: =VLOOKUP($A5,Szamlaszamok!$A4:F1560,2,FALSE) | C5: =VLOOKUP($A5,Szamlaszamok!$A4:F1560,3,FALSE) | D5: =VLOOKUP($A5,Szamlaszamok!$A4:F1560,4,FALSE) | E5: =DATE(YEAR(D5),MONTH(D5),DAY(D5)) | F5: =CONCATENATE(C5,E5) | G5: =TIMEVALUE(D5) | H5: =COUNTIF(Szamlaszamok!A:A,A5) | I5: =SUMIFS(Szamlaszamok!E:E,Szamlaszamok!A:A,Szamlaszamok_nonduplicate!A5)
A6: HNG-2025-5924 | B6: =VLOOKUP($A6,Szamlaszamok!$A5:F1561,2,FALSE) | C6: =VLOOKUP($A6,Szamlaszamok!$A5:F1561,3,FALSE) | D6: =VLOOKUP($A6,Szamlaszamok!$A5:F1561,4,FALSE) | E6: =DATE(YEAR(D6),MONTH(D6),DAY(D6)) | F6: =CONCATENATE(C6,E6) | G6: =TIMEVALUE(D6) | H6: =COUNTIF(Szamlaszamok!A:A,A6) | I6: =SUMIFS(Szamlaszamok!E:E,Szamlaszamok!A:A,Szamlaszamok_nonduplicate!A6)
A7: HNG-2025-5956 | B7: =VLOOKUP($A7,Szamlaszamok!$A6:F1562,2,FALSE) | C7: =VLOOKUP($A7,Szamlaszamok!$A6:F1562,3,FALSE) | D7: =VLOOKUP($A7,Szamlaszamok!$A6:F1562,4,FALSE) | E7: =DATE(YEAR(D7),MONTH(D7),DAY(D7)) | F7: =CONCATENATE(C7,E7) | G7: =TIMEVALUE(D7) | H7: =COUNTIF(Szamlaszamok!A:A,A7) | I7: =SUMIFS(Szamlaszamok!E:E,Szamlaszamok!A:A,Szamlaszamok_nonduplicate!A7)
A8: HNG-2025-5487 | B8: =VLOOKUP($A8,Szamlaszamok!$A7:F1563,2,FALSE) | C8: =VLOOKUP($A8,Szamlaszamok!$A7:F1563,3,FALSE) | D8: =VLOOKUP($A8,Szamlaszamok!$A7:F1563,4,FALSE) | E8: =DATE(YEAR(D8),MONTH(D8),DAY(D8)) | F8: =CONCATENATE(C8,E8) | G8: =TIMEVALUE(D8) | H8: =COUNTIF(Szamlaszamok!A:A,A8) | I8: =SUMIFS(Szamlaszamok!E:E,Szamlaszamok!A:A,Szamlaszamok_nonduplicate!A8)
A9: HNG-2025-5510 | B9: =VLOOKUP($A9,Szamlaszamok!$A8:F1564,2,FALSE) | C9: =VLOOKUP($A9,Szamlaszamok!$A8:F1564,3,FALSE) | D9: =VLOOKUP($A9,Szamlaszamok!$A8:F1564,4,FALSE) | E9: =DATE(YEAR(D9),MONTH(D9),DAY(D9)) | F9: =CONCATENATE(C9,E9) | G9: =TIMEVALUE(D9) | H9: =COUNTIF(Szamlaszamok!A:A,A9) | I9: =SUMIFS(Szamlaszamok!E:E,Szamlaszamok!A:A,Szamlaszamok_nonduplicate!A9)
A10: HNG-2025-5591 | B10: =VLOOKUP($A10,Szamlaszamok!$A9:F1565,2,FALSE) | C10: =VLOOKUP($A10,Szamlaszamok!$A9:F1565,3,FALSE) | D10: =VLOOKUP($A10,Szamlaszamok!$A9:F1565,4,FALSE) | E10: =DATE(YEAR(D10),MONTH(D10),DAY(D10)) | F10: =CONCATENATE(C10,E10) | G10: =TIMEVALUE(D10) | H10: =COUNTIF(Szamlaszamok!A:A,A10) | I10: =SUMIFS(Szamlaszamok!E:E,Szamlaszamok!A:A,Szamlaszamok_nonduplicate!A10)
A11: HNG-2025-5920 | B11: =VLOOKUP($A11,Szamlaszamok!$A10:F1566,2,FALSE) | C11: =VLOOKUP($A11,Szamlaszamok!$A10:F1566,3,FALSE) | D11: =VLOOKUP($A11,Szamlaszamok!$A10:F1566,4,FALSE) | E11: =DATE(YEAR(D11),MONTH(D11),DAY(D11)) | F11: =CONCATENATE(C11,E11) | G11: =TIMEVALUE(D11) | H11: =COUNTIF(Szamlaszamok!A:A,A11) | I11: =SUMIFS(Szamlaszamok!E:E,Szamlaszamok!A:A,Szamlaszamok_nonduplicate!A11)
A12: HNG-2025-5941 | B12: =VLOOKUP($A12,Szamlaszamok!$A11:F1567,2,FALSE) | C12: =VLOOKUP($A12,Szamlaszamok!$A11:F1567,3,FALSE) | D12: =VLOOKUP($A12,Szamlaszamok!$A11:F1567,4,FALSE) | E12: =DATE(YEAR(D12),MONTH(D12),DAY(D12)) | F12: =CONCATENATE(C12,E12) | G12: =TIMEVALUE(D12) | H12: =COUNTIF(Szamlaszamok!A:A,A12) | I12: =SUMIFS(Szamlaszamok!E:E,Szamlaszamok!A:A,Szamlaszamok_nonduplicate!A12)
A13: HNG-2025-5830 | B13: =VLOOKUP($A13,Szamlaszamok!$A12:F1568,2,FALSE) | C13: =VLOOKUP($A13,Szamlaszamok!$A12:F1568,3,FALSE) | D13: =VLOOKUP($A13,Szamlaszamok!$A12:F1568,4,FALSE) | E13: =DATE(YEAR(D13),MONTH(D13),DAY(D13)) | F13: =CONCATENATE(C13,E13) | G13: =TIMEVALUE(D13) | H13: =COUNTIF(Szamlaszamok!A:A,A13) | I13: =SUMIFS(Szamlaszamok!E:E,Szamlaszamok!A:A,Szamlaszamok_nonduplicate!A13)
... A1142: ALDI-2025-41 | B1142: =VLOOKUP($A1142,Szamlaszamok!$A1141:F2697,2,FALSE) | C1142: =VLOOKUP($A1142,Szamlaszamok!$A1141:F2697,3,FALSE) | D1142: =VLOOKUP($A1142,Szamlaszamok!$A1141:F2697,4,FALSE) | E1142: =DATE(YEAR(D1142),MONTH(D1142),DAY(D1142)) | F1142: =CONCATENATE(C1142,E1142) | G1142: =TIMEVALUE(D1142) | H1142: =COUNTIF(Szamlaszamok!A:A,A1142) | I1142: =SUMIFS(Szamlaszamok!E:E,Szamlaszamok!A:A,Szamlaszamok_nonduplicate!A1142)

Sheet Vizsgalati_artetelek
A1: Szamlazas/Vizsgalattipus | B1: Szamlazas/TetelDarab | C1: Szamlazas/Tetelar
A2: Alfa-fötoprotein (AFP) | B2: =COUNTIF(Szamlaszamok!F:F,A2) | C2: =INDEX(Szamlaszamok!E:E,MATCH(A2,Szamlaszamok!F:F,0))
A3: Albumin | B3: =COUNTIF(Szamlaszamok!F:F,A3) | C3: =INDEX(Szamlaszamok!E:E,MATCH(A3,Szamlaszamok!F:F,0))
A4: Anti-Müllerian Hormon (AMH) | B4: =COUNTIF(Szamlaszamok!F:F,A4) | C4: =INDEX(Szamlaszamok!E:E,MATCH(A4,Szamlaszamok!F:F,0))
A5: Amiláz | B5: =COUNTIF(Szamlaszamok!F:F,A5) | C5: =INDEX(Szamlaszamok!E:E,MATCH(A5,Szamlaszamok!F:F,0))
A6: Anti-TPO | B6: =COUNTIF(Szamlaszamok!F:F,A6) | C6: =INDEX(Szamlaszamok!E:E,MATCH(A6,Szamlaszamok!F:F,0))
A7: SYNLAB - AST | B7: =COUNTIF(Szamlaszamok!F:F,A7) | C7: =INDEX(Szamlaszamok!E:E,MATCH(A7,Szamlaszamok!F:F,0))
A8: Direkt bilirubin | B8: =COUNTIF(Szamlaszamok!F:F,A8) | C8: =INDEX(Szamlaszamok!E:E,MATCH(A8,Szamlaszamok!F:F,0))
A9: Totál bilirubin | B9: =COUNTIF(Szamlaszamok!F:F,A9) | C9: =INDEX(Szamlaszamok!E:E,MATCH(A9,Szamlaszamok!F:F,0))
A10: CEA | B10: =COUNTIF(Szamlaszamok!F:F,A10) | C10: =INDEX(Szamlaszamok!E:E,MATCH(A10,Szamlaszamok!F:F,0))
A11: C reaktív protein (CRP) | B11: =COUNTIF(Szamlaszamok!F:F,A11) | C11: =INDEX(Szamlaszamok!E:E,MATCH(A11,Szamlaszamok!F:F,0))
A12: Cyfra 21-1 | B12: =COUNTIF(Szamlaszamok!F:F,A12) | C12: =INDEX(Szamlaszamok!E:E,MATCH(A12,Szamlaszamok!F:F,0))
A13: Csontsűrűség mérés | B13: =COUNTIF(Szamlaszamok!F:F,A13) | C13: =INDEX(Szamlaszamok!E:E,MATCH(A13,Szamlaszamok!F:F,0))
... A235: ALDI- Endokrin II. csomag (Pajzsmirigy bővített) | B235: =COUNTIF(Szamlaszamok!F:F,A235) | C235: =INDEX(Szamlaszamok!E:E,MATCH(A235,Szamlaszamok!F:F,0))
